Traceback (most recent call last):
  File "/home/arian/anaconda3/lib/python3.7/site-packages/jupyter_cache/executors/utils.py", line 64, in single_nb_execution
    **kwargs,
  File "/home/arian/anaconda3/lib/python3.7/site-packages/nbclient/client.py", line 1305, in execute
    return NotebookClient(nb=nb, resources=resources, km=km, **kwargs).execute()
  File "/home/arian/anaconda3/lib/python3.7/site-packages/jupyter_core/utils/__init__.py", line 98, in wrapped
    return loop.run_until_complete(inner)
  File "/home/arian/anaconda3/lib/python3.7/asyncio/base_events.py", line 583, in run_until_complete
    return future.result()
  File "/home/arian/anaconda3/lib/python3.7/site-packages/nbclient/client.py", line 706, in async_execute
    cell, index, execution_count=self.code_cells_executed + 1
  File "/home/arian/anaconda3/lib/python3.7/site-packages/nbclient/client.py", line 1058, in async_execute_cell
    await self._check_raise_for_error(cell, cell_index, exec_reply)
  File "/home/arian/anaconda3/lib/python3.7/site-packages/nbclient/client.py", line 914, in _check_raise_for_error
    raise CellExecutionError.from_cell_and_msg(cell, exec_reply_content)
nbclient.exceptions.CellExecutionError: An error occurred while executing the following cell:
------------------
from google.colab import drive
drive.mount('/content/drive')
------------------


[0;31m---------------------------------------------------------------------------[0m
[0;31mModuleNotFoundError[0m                       Traceback (most recent call last)
[0;32m<ipython-input-1-d5df0069828e>[0m in [0;36m<module>[0;34m[0m
[0;32m----> 1[0;31m [0;32mfrom[0m [0mgoogle[0m[0;34m.[0m[0mcolab[0m [0;32mimport[0m [0mdrive[0m[0;34m[0m[0;34m[0m[0m
[0m[1;32m      2[0m [0mdrive[0m[0;34m.[0m[0mmount[0m[0;34m([0m[0;34m'/content/drive'[0m[0;34m)[0m[0;34m[0m[0;34m[0m[0m

[0;31mModuleNotFoundError[0m: No module named 'google'

